Workbook

Sheet Dashboard
C2: Mintresponse — Work Order Dashboard
C3: ="All amounts in USD, excluding sales tax · As of "&TEXT(TODAY(),"mmmm d, yyyy")
B5: WORK ORDERS | E5: INVOICED REVENUE | H5: GROSS PROFIT* | K5: NET PROFIT*
B6: ='Work Orders'!A5 | E6: ='Work Orders'!B5 | H6: ='Work Orders'!C5 | K6: ='Work Orders'!D5
B7: =COUNTIFS('Work Orders'!$A$11:$A$1010,"<>",'Work Orders'!$R$11:$R$1010,"<>Completed",'Work Orders'!$R$11:$R$1010,"<>Cancelled")&" open" | H7: =IF(N('Work Orders'!B5)=0,"",TEXT('Work Orders'!C5/'Work Orders'!B5,"0.0%")&" margin") | K7: =IF(N('Work Orders'!B5)=0,"",TEXT('Work Orders'!D5/'Work Orders'!B5,"0.0%")&" margin")
B9: BALANCE DUE* | E9: OVERDUE | H9: NEEDS FINANCIAL INPUT | K9: OVER THE APPROVED NTE
B10: ='Work Orders'!E5 | E10: =SUMIFS('Work Orders'!$AH$11:$AH$1010,'Work Orders'!$AM$11:$AM$1010,">0") | H10: ='Work Orders'!F5 | K10: =COUNTIF('Work Orders'!$AJ$11:$AJ$1010,"*exceeds NTE")
B11: =COUNTIF('Work Orders'!$AL$11:$AL$1010,"?*")&" open invoices" | E11: =COUNTIF('Work Orders'!$AM$11:$AM$1010,">0")&" invoices past due" | H11: ="work orders with an Enter… status" | K11: ="quotes or invoices above NTE"
B12: *Totals include calculated rows only. Complete financial inputs before relying on profit totals.
B14: Work orders by status
B15: WO status | C15: Count
B16: New | C16: =COUNTIF('Work Orders'!$R$11:$R$1010,B16)
B17: Scheduled | C17: =COUNTIF('Work Orders'!$R$11:$R$1010,B17)
B18: In progress | C18: =COUNTIF('Work Orders'!$R$11:$R$1010,B18)
B19: Awaiting parts | C19: =COUNTIF('Work Orders'!$R$11:$R$1010,B19)
B20: Awaiting approval | C20: =COUNTIF('Work Orders'!$R$11:$R$1010,B20)
B21: Completed | C21: =COUNTIF('Work Orders'!$R$11:$R$1010,B21)
B22: Cancelled | C22: =COUNTIF('Work Orders'!$R$11:$R$1010,B22)
B23: No status | C23: =COUNTIFS('Work Orders'!$A$11:$A$1010,"<>",'Work Orders'!$R$11:$R$1010,"")
B28: Receivables aging
B29: Days past due | C29: Balance due | D29: Invoices
B30: Not yet due | C30: =SUMIFS('Work Orders'!$AH$11:$AH$1010,'Work Orders'!$AL$11:$AL$1010,B30) | D30: =COUNTIF('Work Orders'!$AL$11:$AL$1010,B30)
B31: 1-30 days | C31: =SUMIFS('Work Orders'!$AH$11:$AH$1010,'Work Orders'!$AL$11:$AL$1010,B31) | D31: =COUNTIF('Work Orders'!$AL$11:$AL$1010,B31)
B32: 31-60 days | C32: =SUMIFS('Work Orders'!$AH$11:$AH$1010,'Work Orders'!$AL$11:$AL$1010,B32) | D32: =COUNTIF('Work Orders'!$AL$11:$AL$1010,B32)
B33: 61-90 days | C33: =SUMIFS('Work Orders'!$AH$11:$AH$1010,'Work Orders'!$AL$11:$AL$1010,B33) | D33: =COUNTIF('Work Orders'!$AL$11:$AL$1010,B33)
B34: Over 90 days | C34: =SUMIFS('Work Orders'!$AH$11:$AH$1010,'Work Orders'!$AL$11:$AL$1010,B34) | D34: =COUNTIF('Work Orders'!$AL$11:$AL$1010,B34)
B35: No due date | C35: =SUMIFS('Work Orders'!$AH$11:$AH$1010,'Work Orders'!$AL$11:$AL$1010,B35) | D35: =COUNTIF('Work Orders'!$AL$11:$AL$1010,B35)
B42: Top clients by invoice revenue
B43: Client | C43: Revenue
B44: =IFERROR(IF(INDEX(Clients!$D$6:$D$205,MATCH(1,Clients!$I$6:$I$205,0))>0,INDEX(Clients!$B$6:$B$205,MATCH(1,Clients!$I$6:$I$205,0)),""),"") | C44: =IF(B44="","",INDEX(Clients!$D$6:$D$205,MATCH(1,Clients!$I$6:$I$205,0)))
B45: =IFERROR(IF(INDEX(Clients!$D$6:$D$205,MATCH(2,Clients!$I$6:$I$205,0))>0,INDEX(Clients!$B$6:$B$205,MATCH(2,Clients!$I$6:$I$205,0)),""),"") | C45: =IF(B45="","",INDEX(Clients!$D$6:$D$205,MATCH(2,Clients!$I$6:$I$205,0)))
B46: =IFERROR(IF(INDEX(Clients!$D$6:$D$205,MATCH(3,Clients!$I$6:$I$205,0))>0,INDEX(Clients!$B$6:$B$205,MATCH(3,Clients!$I$6:$I$205,0)),""),"") | C46: =IF(B46="","",INDEX(Clients!$D$6:$D$205,MATCH(3,Clients!$I$6:$I$205,0)))
B47: =IFERROR(IF(INDEX(Clients!$D$6:$D$205,MATCH(4,Clients!$I$6:$I$205,0))>0,INDEX(Clients!$B$6:$B$205,MATCH(4,Clients!$I$6:$I$205,0)),""),"") | C47: =IF(B47="","",INDEX(Clients!$D$6:$D$205,MATCH(4,Clients!$I$6:$I$205,0)))
B48: =IFERROR(IF(INDEX(Clients!$D$6:$D$205,MATCH(5,Clients!$I$6:$I$205,0))>0,INDEX(Clients!$B$6:$B$205,MATCH(5,Clients!$I$6:$I$205,0)),""),"") | C48: =IF(B48="","",INDEX(Clients!$D$6:$D$205,MATCH(5,Clients!$I$6:$I$205,0)))
B49: =IFERROR(IF(INDEX(Clients!$D$6:$D$205,MATCH(6,Clients!$I$6:$I$205,0))>0,INDEX(Clients!$B$6:$B$205,MATCH(6,Clients!$I$6:$I$205,0)),""),"") | C49: =IF(B49="","",INDEX(Clients!$D$6:$D$205,MATCH(6,Clients!$I$6:$I$205,0)))
B50: =IFERROR(IF(INDEX(Clients!$D$6:$D$205,MATCH(7,Clients!$I$6:$I$205,0))>0,INDEX(Clients!$B$6:$B$205,MATCH(7,Clients!$I$6:$I$205,0)),""),"") | C50: =IF(B50="","",INDEX(Clients!$D$6:$D$205,MATCH(7,Clients!$I$6:$I$205,0)))
B51: =IFERROR(IF(INDEX(Clients!$D$6:$D$205,MATCH(8,Clients!$I$6:$I$205,0))>0,INDEX(Clients!$B$6:$B$205,MATCH(8,Clients!$I$6:$I$205,0)),""),"") | C51: =IF(B51="","",INDEX(Clients!$D$6:$D$205,MATCH(8,Clients!$I$6:$I$205,0)))
B56: Most overdue invoices | E56: Full list on the Receivables sheet
B57: WO # | C57: Client | D57: Balance due | E57: Days overdue | F57: Payment due | G57: Invoice # | H57: Handler
B58: =IF(N(Receivables!$M$7)>0,Receivables!C7,"") | C58: =IF(N(Receivables!$M$7)>0,Receivables!D7,"") | D58: =IF(N(Receivables!$M$7)>0,Receivables!L7,"") | E58: =IF(N(Receivables!$M$7)>0,Receivables!M7,"") | F58: =IF(N(Receivables!$M$7)>0,Receivables!I7,"") | G58: =IF(N(Receivables!$M$7)>0,Receivables!F7,"") | H58: =IF(N(Receivables!$M$7)>0,Receivables!O7,"")
...

Sheet Work Orders
A2: Mintresponse LLC — Work Order List
A4: Work orders | B4: Invoiced revenue | C4: Gross profit* | D4: Net profit* | E4: Balance due* | F4: Needs financial input
A5: =COUNTA(A11:A1010) | B5: =SUM(Z11:Z1010) | C5: =SUM(J11:J1010) | D5: =SUM(AE11:AE1010) | E5: =SUM(AH11:AH1010) | F5: =COUNTIFS(AK11:AK1010,"Enter*")
A7: Yellow cells = enter data. Blue/green cells = formulas. 1,000 prepared rows. Dashboard, Receivables and Clients update automatically.
A8: *Totals include calculated rows only. Complete financial inputs before using profit totals. All amounts in USD, excluding sales tax.
A10: WO # | B10: Client | C10: Assignees | D10: Store name | E10: Location | F10: ETA | G10: Parts ordered / status | H10: Direct cost | I10: Approved NTE | J10: Gross profit | K10: Gross margin % | L10: Expected NTE / quote | M10: Job type / scope | N10: Handler | O10: Tech | P10: Notes | Q10: Invoice # | R10: WO status | S10: Address | T10: Date in | U10: Invoice sent date | V10: Invoice status | W10: Payment method | X10: Payment due | Y10: Target markup % | Z10: Invoice revenue | AA10: Actual markup % | AB10: Allocated overhead | AC10: Payment / admin fees | AD10: Other expenses / tax | AE10: Net profit | AF10: Net margin % | AG10: Amount received | AH10: Balance due | AI10: Payment terms (days) | AJ10: NTE check | AK10: Financial input status | AL10: Aging bucket | AM10: Days overdue | AN10: AR sort key | AO10: AR order | AP10: Client #
J11: =IF(OR(A11="",COUNT(H11)=0,COUNT(Z11)=0),"",ROUND(Z11-H11,2)) | K11: =IF(COUNT(J11)=0,"",IF(Z11=0,"n.a.",J11/Z11)) | L11: =IF(OR(A11="",COUNT(H11)=0,COUNT(Y11)=0),"",ROUND(H11*(1+Y11),2)) | X11: =IF(OR(A11="",COUNT(U11)=0,COUNT(AI11)=0),"",U11+AI11) | AA11: =IF(COUNT(J11)=0,"",IF(H11=0,"n.a.",J11/H11)) | AE11: =IF(OR(COUNT(J11)=0,COUNT(AB11:AD11)<3),"",ROUND(J11-SUM(AB11:AD11),2)) | AF11: =IF(COUNT(AE11)=0,"",IF(Z11=0,"n.a.",AE11/Z11)) | AH11: =IF(OR(A11="",COUNT(Z11)=0,COUNT(AG11)=0),"",ROUND(Z11-AG11,2)) | AJ11: =IF(A11="","",IF(COUNT(I11)=0,"Enter approved NTE",IF(COUNT(Z11)>0,IF(Z11>I11,"Invoice exceeds NTE","Invoice within NTE"),IF(COUNT(L11)=0,"Enter quote inputs",IF(L11>I11,"Quote exceeds NTE","Quote within NTE"))))) | AK11: =IF(A11="","",IF(COUNT(H11)=0,"Enter direct cost",IF(COUNT(Z11)=0,"Enter invoice revenue",IF(COUNT(AB11:AD11)<3,"Enter expenses (0 if none)","Complete")))) | AL11: =IF(A11="","",IF(NOT(AND(COUNT(AH11)=1,N(AH11)>0.004,V11<>"Void",V11<>"Not invoiced",V11<>"Draft")),"",IF(COUNT(X11)=0,"No due date",IF(TODAY()-X11<=0,"Not yet due",IF(TODAY()-X11<=30,"1-30 days",IF(TODAY()-X11<=60,"31-60 days",IF(TODAY()-X11<=90,"61-90 days","Over 90 days"))))))) | AM11: =IF(OR(AL11="",AL11="No due date"),"",MAX(TODAY()-X11,0)) | AN11: =IF(AL11="","",IF(COUNT(X11)=0,-100000,TODAY()-X11)) | AO11: =IF(AN11="","",COUNTIF(AN$11:AN$1010,">"&AN11)+COUNTIF(AN$11:AN11,AN11)) | AP11: =IF(OR(A11="",B11=""),"",IF(COUNTIF(B$11:B11,B11)=1,MAX(AP$10:AP10)+1,""))
J12: =IF(OR(A12="",COUNT(H12)=0,COUNT(Z12)=0),"",ROUND(Z12-H12,2)) | K12: =IF(COUNT(J12)=0,"",IF(Z12=0,"n.a.",J12/Z12)) | L12: =IF(OR(A12="",COUNT(H12)=0,COUNT(Y12)=0),"",ROUND(H12*(1+Y12),2)) | X12: =IF(OR(A12="",COUNT(U12)=0,COUNT(AI12)=0),"",U12+AI12) | AA12: =IF(COUNT(J12)=0,"",IF(H12=0,"n.a.",J12/H12)) | AE12: =IF(OR(COUNT(J12)=0,COUNT(AB12:AD12)<3),"",ROUND(J12-SUM(AB12:AD12),2)) | AF12: =IF(COUNT(AE12)=0,"",IF(Z12=0,"n.a.",AE12/Z12)) | AH12: =IF(OR(A12="",COUNT(Z12)=0,COUNT(AG12)=0),"",ROUND(Z12-AG12,2)) | AJ12: =IF(A12="","",IF(COUNT(I12)=0,"Enter approved NTE",IF(COUNT(Z12)>0,IF(Z12>I12,"Invoice exceeds NTE","Invoice within NTE"),IF(COUNT(L12)=0,"Enter quote inputs",IF(L12>I12,"Quote exceeds NTE","Quote within NTE"))))) | AK12: =IF(A12="","",IF(COUNT(H12)=0,"Enter direct cost",IF(COUNT(Z12)=0,"Enter invoice revenue",IF(COUNT(AB12:AD12)<3,"Enter expenses (0 if none)","Complete")))) | AL12: =IF(A12="","",IF(NOT(AND(COUNT(AH12)=1,N(AH12)>0.004,V12<>"Void",V12<>"Not invoiced",V12<>"Draft")),"",IF(COUNT(X12)=0,"No due date",IF(TODAY()-X12<=0,"Not yet due",IF(TODAY()-X12<=30,"1-30 days",IF(TODAY()-X12<=60,"31-60 days",IF(TODAY()-X12<=90,"61-90 days","Over 90 days"))))))) | AM12: =IF(OR(AL12="",AL12="No due date"),"",MAX(TODAY()-X12,0)) | AN12: =IF(AL12="","",IF(COUNT(X12)=0,-100000,TODAY()-X12)) | AO12: =IF(AN12="","",COUNTIF(AN$11:AN$1010,">"&AN12)+COUNTIF(AN$11:AN12,AN12)) | AP12: =IF(OR(A12="",B12=""),"",IF(COUNTIF(B$11:B12,B12)=1,MAX(AP$10:AP11)+1,""))
J13: =IF(OR(A13="",COUNT(H13)=0,COUNT(Z13)=0),"",ROUND(Z13-H13,2)) | K13: =IF(COUNT(J13)=0,"",IF(Z13=0,"n.a.",J13/Z13)) | L13: =IF(OR(A13="",COUNT(H13)=0,COUNT(Y13)=0),"",ROUND(H13*(1+Y13),2)) | X13: =IF(OR(A13="",COUNT(U13)=0,COUNT(AI13)=0),"",U13+AI13) | AA13: =IF(COUNT(J13)=0,"",IF(H13=0,"n.a.",J13/H13)) | AE13: =IF(OR(COUNT(J13)=0,COUNT(AB13:AD13)<3),"",ROUND(J13-SUM(AB13:AD13),2)) | AF13: =IF(COUNT(AE13)=0,"",IF(Z13=0,"n.a.",AE13/Z13)) | AH13: =IF(OR(A13="",COUNT(Z13)=0,COUNT(AG13)=0),"",ROUND(Z13-AG13,2)) | AJ13: =IF(A13="","",IF(COUNT(I13)=0,"Enter approved NTE",IF(COUNT(Z13)>0,IF(Z13>I13,"Invoice exceeds NTE","Invoice within NTE"),IF(COUNT(L13)=0,"Enter quote inputs",IF(L13>I13,"Quote exceeds NTE","Quote within NTE"))))) | AK13: =IF(A13="","",IF(COUNT(H13)=0,"Enter direct cost",IF(COUNT(Z13)=0,"Enter invoice revenue",IF(COUNT(AB13:AD13)<3,"Enter expenses (0 if none)","Complete")))) | AL13: =IF(A13="","",IF(NOT(AND(COUNT(AH13)=1,N(AH13)>0.004,V13<>"Void",V13<>"Not invoiced",V13<>"Draft")),"",IF(COUNT(X13)=0,"No due date",IF(TODAY()-X13<=0,"Not yet due",IF(TODAY()-X13<=30,"1-30 days",IF(TODAY()-X13<=60,"31-60 days",IF(TODAY()-X13<=90,"61-90 days","Over 90 days"))))))) | AM13: =IF(OR(AL13="",AL13="No due date"),"",MAX(TODAY()-X13,0)) | AN13: =IF(AL13="","",IF(COUNT(X13)=0,-100000,TODAY()-X13)) | AO13: =IF(AN13="","",COUNTIF(AN$11:AN$1010,">"&AN13)+COUNTIF(AN$11:AN13,AN13)) | AP13: =IF(OR(A13="",B13=""),"",IF(COUNTIF(B$11:B13,B13)=1,MAX(AP$10:AP12)+1,""))
J14: =IF(OR(A14="",COUNT(H14)=0,COUNT(Z14)=0),"",ROUND(Z14-H14,2)) | K14: =IF(COUNT(J14)=0,"",IF(Z14=0,"n.a.",J14/Z14)) | L14: =IF(OR(A14="",COUNT(H14)=0,COUNT(Y14)=0),"",ROUND(H14*(1+Y14),2)) | X14: =IF(OR(A14="",COUNT(U14)=0,COUNT(AI14)=0),"",U14+AI14) | AA14: =IF(COUNT(J14)=0,"",IF(H14=0,"n.a.",J14/H14)) | AE14: =IF(OR(COUNT(J14)=0,COUNT(AB14:AD14)<3),"",ROUND(J14-SUM(AB14:AD14),2)) | AF14: =IF(COUNT(AE14)=0,"",IF(Z14=0,"n.a.",AE14/Z14)) | AH14: =IF(OR(A14="",COUNT(Z14)=0,COUNT(AG14)=0),"",ROUND(Z14-AG14,2)) | AJ14: =IF(A14="","",IF(COUNT(I14)=0,"Enter approved NTE",IF(COUNT(Z14)>0,IF(Z14>I14,"Invoice exceeds NTE","Invoice within NTE"),IF(COUNT(L14)=0,"Enter quote inputs",IF(L14>I14,"Quote exceeds NTE","Quote within NTE"))))) | AK14: =IF(A14="","",IF(COUNT(H14)=0,"Enter direct cost",IF(COUNT(Z14)=0,"Enter invoice revenue",IF(COUNT(AB14:AD14)<3,"Enter expenses (0 if none)","Complete")))) | AL14: =IF(A14="","",IF(NOT(AND(COUNT(AH14)=1,N(AH14)>0.004,V14<>"Void",V14<>"Not invoiced",V14<>"Draft")),"",IF(COUNT(X14)=0,"No due date",IF(TODAY()-X14<=0,"Not yet due",IF(TODAY()-X14<=30,"1-30 days",IF(TODAY()-X14<=60,"31-60 days",IF(TODAY()-X14<=90,"61-90 days","Over 90 days"))))))) | AM14: =IF(OR(AL14="",AL14="No due date"),"",MAX(TODAY()-X14,0)) | AN14: =IF(AL14="","",IF(COUNT(X14)=0,-100000,TODAY()-X14)) | AO14: =IF(AN14="","",COUNTIF(AN$11:AN$1010,">"&AN14)+COUNTIF(AN$11:AN14,AN14)) | AP14: =IF(OR(A14="",B14=""),"",IF(COUNTIF(B$11:B14,B14)=1,MAX(AP$10:AP13)+1,""))
J15: =IF(OR(A15="",COUNT(H15)=0,COUNT(Z15)=0),"",ROUND(Z15-H15,2)) | K15: =IF(COUNT(J15)=0,"",IF(Z15=0,"n.a.",J15/Z15)) | L15: =IF(OR(A15="",COUNT(H15)=0,COUNT(Y15)=0),"",ROUND(H15*(1+Y15),2)) | X15: =IF(OR(A15="",COUNT(U15)=0,COUNT(AI15)=0),"",U15+AI15) | AA15: =IF(COUNT(J15)=0,"",IF(H15=0,"n.a.",J15/H15)) | AE15: =IF(OR(COUNT(J15)=0,COUNT(AB15:AD15)<3),"",ROUND(J15-SUM(AB15:AD15),2)) | AF15: =IF(COUNT(AE15)=0,"",IF(Z15=0,"n.a.",AE15/Z15)) | AH15: =IF(OR(A15="",COUNT(Z15)=0,COUNT(AG15)=0),"",ROUND(Z15-AG15,2)) | AJ15: =IF(A15="","",IF(COUNT(I15)=0,"Enter approved NTE",IF(COUNT(Z15)>0,IF(Z15>I15,"Invoice exceeds NTE","Invoice within NTE"),IF(COUNT(L15)=0,"Enter quote inputs",IF(L15>I15,"Quote exceeds NTE","Quote within NTE"))))) | AK15: =IF(A15="","",IF(COUNT(H15)=0,"Enter direct cost",IF(COUNT(Z15)=0,"Enter invoice revenue",IF(COUNT(AB15:AD15)<3,"Enter expenses (0 if none)","Complete")))) | AL15: =IF(A15="","",IF(NOT(AND(COUNT(AH15)=1,N(AH15)>0.004,V15<>"Void",V15<>"Not invoiced",V15<>"Draft")),"",IF(COUNT(X15)=0,"No due date",IF(TODAY()-X15<=0,"Not yet due",IF(TODAY()-X15<=30,"1-30 days",IF(TODAY()-X15<=60,"31-60 days",IF(TODAY()-X15<=90,"61-90 days","Over 90 days"))))))) | AM15: =IF(OR(AL15="",AL15="No due date"),"",MAX(TODAY()-X15,0)) | AN15: =IF(AL15="","",IF(COUNT(X15)=0,-100000,TODAY()-X15)) | AO15: =IF(AN15="","",COUNTIF(AN$11:AN$1010,">"&AN15)+COUNTIF(AN$11:AN15,AN15)) | AP15: =IF(OR(A15="",B15=""),"",IF(COUNTIF(B$11:B15,B15)=1,MAX(AP$10:AP14)+1,""))
J16: =IF(OR(A16="",COUNT(H16)=0,COUNT(Z16)=0),"",ROUND(Z16-H16,2)) | K16: =IF(COUNT(J16)=0,"",IF(Z16=0,"n.a.",J16/Z16)) | L16: =IF(OR(A16="",COUNT(H16)=0,COUNT(Y16)=0),"",ROUND(H16*(1+Y16),2)) | X16: =IF(OR(A16="",COUNT(U16)=0,COUNT(AI16)=0),"",U16+AI16) | AA16: =IF(COUNT(J16)=0,"",IF(H16=0,"n.a.",J16/H16)) | AE16: =IF(OR(COUNT(J16)=0,COUNT(AB16:AD16)<3),"",ROUND(J16-SUM(AB16:AD16),2)) | AF16: =IF(COUNT(AE16)=0,"",IF(Z16=0,"n.a.",AE16/Z16)) | AH16: =IF(OR(A16="",COUNT(Z16)=0,COUNT(AG16)=0),"",ROUND(Z16-AG16,2)) | AJ16: =IF(A16="","",IF(COUNT(I16)=0,"Enter approved NTE",IF(COUNT(Z16)>0,IF(Z16>I16,"Invoice exceeds NTE","Invoice within NTE"),IF(COUNT(L16)=0,"Enter quote inputs",IF(L16>I16,"Quote exceeds NTE","Quote within NTE"))))) | AK16: =IF(A16="","",IF(COUNT(H16)=0,"Enter direct cost",IF(COUNT(Z16)=0,"Enter invoice revenue",IF(COUNT(AB16:AD16)<3,"Enter expenses (0 if none)","Complete")))) | AL16: =IF(A16="","",IF(NOT(AND(COUNT(AH16)=1,N(AH16)>0.004,V16<>"Void",V16<>"Not invoiced",V16<>"Draft")),"",IF(COUNT(X16)=0,"No due date",IF(TODAY()-X16<=0,"Not yet due",IF(TODAY()-X16<=30,"1-30 days",IF(TODAY()-X16<=60,"31-60 days",IF(TODAY()-X16<=90,"61-90 days","Over 90 days"))))))) | AM16: =IF(OR(AL16="",AL16="No due date"),"",MAX(TODAY()-X16,0)) | AN16: =IF(AL16="","",IF(COUNT(X16)=0,-100000,TODAY()-X16)) | AO16: =IF(AN16="","",COUNTIF(AN$11:AN$1010,">"&AN16)+COUNTIF(AN$11:AN16,AN16)) | AP16: =IF(OR(A16="",B16=""),"",IF(COUNTIF(B$11:B16,B16)=1,MAX(AP$10:AP15)+1,""))
J17: =IF(OR(A17="",COUNT(H17)=0,COUNT(Z17)=0),"",ROUND(Z17-H17,2)) | K17: =IF(COUNT(J17)=0,"",IF(Z17=0,"n.a.",J17/Z17)) | L17: =IF(OR(A17="",COUNT(H17)=0,COUNT(Y17)=0),"",ROUND(H17*(1+Y17),2)) | X17: =IF(OR(A17="",COUNT(U17)=0,COUNT(AI17)=0),"",U17+AI17) | AA17: =IF(COUNT(J17)=0,"",IF(H17=0,"n.a.",J17/H17)) | AE17: =IF(OR(COUNT(J17)=0,COUNT(AB17:AD17)<3),"",ROUND(J17-SUM(AB17:AD17),2)) | AF17: =IF(COUNT(AE17)=0,"",IF(Z17=0,"n.a.",AE17/Z17)) | AH17: =IF(OR(A17="",COUNT(Z17)=0,COUNT(AG17)=0),"",ROUND(Z17-AG17,2)) | AJ17: =IF(A17="","",IF(COUNT(I17)=0,"Enter approved NTE",IF(COUNT(Z17)>0,IF(Z17>I17,"Invoice exceeds NTE","Invoice within NTE"),IF(COUNT(L17)=0,"Enter quote inputs",IF(L17>I17,"Quote exceeds NTE","Quote within NTE"))))) | AK17: =IF(A17="","",IF(COUNT(H17)=0,"Enter direct cost",IF(COUNT(Z17)=0,"Enter invoice revenue",IF(COUNT(AB17:AD17)<3,"Enter expenses (0 if none)","Complete")))) | AL17: =IF(A17="","",IF(NOT(AND(COUNT(AH17)=1,N(AH17)>0.004,V17<>"Void",V17<>"Not invoiced",V17<>"Draft")),"",IF(COUNT(X17)=0,"No due date",IF(TODAY()-X17<=0,"Not yet due",IF(TODAY()-X17<=30,"1-30 days",IF(TODAY()-X17<=60,"31-60 days",IF(TODAY()-X17<=90,"61-90 days","Over 90 days"))))))) | AM17: =IF(OR(AL17="",AL17="No due date"),"",MAX(TODAY()-X17,0)) | AN17: =IF(AL17="","",IF(COUNT(X17)=0,-100000,TODAY()-X17)) | AO17: =IF(AN17="","",COUNTIF(AN$11:AN$1010,">"&AN17)+COUNTIF(AN$11:AN17,AN17)) | AP17: =IF(OR(A17="",B17=""),"",IF(COUNTIF(B$11:B17,B17)=1,MAX(AP$10:AP16)+1,""))
J18: =IF(OR(A18="",COUNT(H18)=0,COUNT(Z18)=0),"",ROUND(Z18-H18,2)) | K18: =IF(COUNT(J18)=0,"",IF(Z18=0,"n.a.",J18/Z18)) | L18: =IF(OR(A18="",COUNT(H18)=0,COUNT(Y18)=0),"",ROUND(H18*(1+Y18),2)) | X18: =IF(OR(A18="",COUNT(U18)=0,COUNT(AI18)=0),"",U18+AI18) | AA18: =IF(COUNT(J18)=0,"",IF(H18=0,"n.a.",J18/H18)) | AE18: =IF(OR(COUNT(J18)=0,COUNT(AB18:AD18)<3),"",ROUND(J18-SUM(AB18:AD18),2)) | AF18: =IF(COUNT(AE18)=0,"",IF(Z18=0,"n.a.",AE18/Z18)) | AH18: =IF(OR(A18="",COUNT(Z18)=0,COUNT(AG18)=0),"",ROUND(Z18-AG18,2)) | AJ18: =IF(A18="","",IF(COUNT(I18)=0,"Enter approved NTE",IF(COUNT(Z18)>0,IF(Z18>I18,"Invoice exceeds NTE","Invoice within NTE"),IF(COUNT(L18)=0,"Enter quote inputs",IF(L18>I18,"Quote exceeds NTE","Quote within NTE"))))) | AK18: =IF(A18="","",IF(COUNT(H18)=0,"Enter direct cost",IF(COUNT(Z18)=0,"Enter invoice revenue",IF(COUNT(AB18:AD18)<3,"Enter expenses (0 if none)","Complete")))) | AL18: =IF(A18="","",IF(NOT(AND(COUNT(AH18)=1,N(AH18)>0.004,V18<>"Void",V18<>"Not invoiced",V18<>"Draft")),"",IF(COUNT(X18)=0,"No due date",IF(TODAY()-X18<=0,"Not yet due",IF(TODAY()-X18<=30,"1-30 days",IF(TODAY()-X18<=60,"31-60 days",IF(TODAY()-X18<=90,"61-90 days","Over 90 days"))))))) | AM18: =IF(OR(AL18="",AL18="No due date"),"",MAX(TODAY()-X18,0)) | AN18: =IF(AL18="","",IF(COUNT(X18)=0,-100000,TODAY()-X18)) | AO18: =IF(AN18="","",COUNTIF(AN$11:AN$1010,">"&AN18)+COUNTIF(AN$11:AN18,AN18)) | AP18: =IF(OR(A18="",B18=""),"",IF(COUNTIF(B$11:B18,B18)=1,MAX(AP$10:AP17)+1,""))
J19: =IF(OR(A19="",COUNT(H19)=0,COUNT(Z19)=0),"",ROUND(Z19-H19,2)) | K19: =IF(COUNT(J19)=0,"",IF(Z19=0,"n.a.",J19/Z19)) | L19: =IF(OR(A19="",COUNT(H19)=0,COUNT(Y19)=0),"",ROUND(H19*(1+Y19),2)) | X19: =IF(OR(A19="",COUNT(U19)=0,COUNT(AI19)=0),"",U19+AI19) | AA19: =IF(COUNT(J19)=0,"",IF(H19=0,"n.a.",J19/H19)) | AE19: =IF(OR(COUNT(J19)=0,COUNT(AB19:AD19)<3),"",ROUND(J19-SUM(AB19:AD19),2)) | AF19: =IF(COUNT(AE19)=0,"",IF(Z19=0,"n.a.",AE19/Z19)) | AH19: =IF(OR(A19="",COUNT(Z19)=0,COUNT(AG19)=0),"",ROUND(Z19-AG19,2)) | AJ19: =IF(A19="","",IF(COUNT(I19)=0,"Enter approved NTE",IF(COUNT(Z19)>0,IF(Z19>I19,"Invoice exceeds NTE","Invoice within NTE"),IF(COUNT(L19)=0,"Enter quote inputs",IF(L19>I19,"Quote exceeds NTE","Quote within NTE"))))) | AK19: =IF(A19="","",IF(COUNT(H19)=0,"Enter direct cost",IF(COUNT(Z19)=0,"Enter invoice revenue",IF(COUNT(AB19:AD19)<3,"Enter expenses (0 if none)","Complete")))) | AL19: =IF(A19="","",IF(NOT(AND(COUNT(AH19)=1,N(AH19)>0.004,V19<>"Void",V19<>"Not invoiced",V19<>"Draft")),"",IF(COUNT(X19)=0,"No due date",IF(TODAY()-X19<=0,"Not yet due",IF(TODAY()-X19<=30,"1-30 days",IF(TODAY()-X19<=60,"31-60 days",IF(TODAY()-X19<=90,"61-90 days","Over 90 days"))))))) | AM19: =IF(OR(AL19="",AL19="No due date"),"",MAX(TODAY()-X19,0)) | AN19: =IF(AL19="","",IF(COUNT(X19)=0,-100000,TODAY()-X19)) | AO19: =IF(AN19="","",COUNTIF(AN$11:AN$1010,">"&AN19)+COUNTIF(AN$11:AN19,AN19)) | AP19: =IF(OR(A19="",B19=""),"",IF(COUNTIF(B$11:B19,B19)=1,MAX(AP$10:AP18)+1,""))
J20: =IF(OR(A20="",COUNT(H20)=0,COUNT(Z20)=0),"",ROUND(Z20-H20,2)) | K20: =IF(COUNT(J20)=0,"",IF(Z20=0,"n.a.",J20/Z20)) | L20: =IF(OR(A20="",COUNT(H20)=0,COUNT(Y20)=0),"",ROUND(H20*(1+Y20),2)) | X20: =IF(OR(A20="",COUNT(U20)=0,COUNT(AI20)=0),"",U20+AI20) | AA20: =IF(COUNT(J20)=0,"",IF(H20=0,"n.a.",J20/H20)) | AE20: =IF(OR(COUNT(J20)=0,COUNT(AB20:AD20)<3),"",ROUND(J20-SUM(AB20:AD20),2)) | AF20: =IF(COUNT(AE20)=0,"",IF(Z20=0,"n.a.",AE20/Z20)) | AH20: =IF(OR(A20="",COUNT(Z20)=0,COUNT(AG20)=0),"",ROUND(Z20-AG20,2)) | AJ20: =IF(A20="","",IF(COUNT(I20)=0,"Enter approved NTE",IF(COUNT(Z20)>0,IF(Z20>I20,"Invoice exceeds NTE","Invoice within NTE"),IF(COUNT(L20)=0,"Enter quote inputs",IF(L20>I20,"Quote exceeds NTE","Quote within NTE"))))) | AK20: =IF(A20="","",IF(COUNT(H20)=0,"Enter direct cost",IF(COUNT(Z20)=0,"Enter invoice revenue",IF(COUNT(AB20:AD20)<3,"Enter expenses (0 if none)","Complete")))) | AL20: =IF(A20="","",IF(NOT(AND(COUNT(AH20)=1,N(AH20)>0.004,V20<>"Void",V20<>"Not invoiced",V20<>"Draft")),"",IF(COUNT(X20)=0,"No due date",IF(TODAY()-X20<=0,"Not yet due",IF(TODAY()-X20<=30,"1-30 days",IF(TODAY()-X20<=60,"31-60 days",IF(TODAY()-X20<=90,"61-90 days","Over 90 days"))))))) | AM20: =IF(OR(AL20="",AL20="No due date"),"",MAX(TODAY()-X20,0)) | AN20: =IF(AL20="","",IF(COUNT(X20)=0,-100000,TODAY()-X20)) | AO20: =IF(AN20="","",COUNTIF(AN$11:AN$1010,">"&AN20)+COUNTIF(AN$11:AN20,AN20)) | AP20: =IF(OR(A20="",B20=""),"",IF(COUNTIF(B$11:B20,B20)=1,MAX(AP$10:AP19)+1,""))
J21: =IF(OR(A21="",COUNT(H21)=0,COUNT(Z21)=0),"",ROUND(Z21-H21,2)) | K21: =IF(COUNT(J21)=0,"",IF(Z21=0,"n.a.",J21/Z21)) | L21: =IF(OR(A21="",COUNT(H21)=0,COUNT(Y21)=0),"",ROUND(H21*(1+Y21),2)) | X21: =IF(OR(A21="",COUNT(U21)=0,COUNT(AI21)=0),"",U21+AI21) | AA21: =IF(COUNT(J21)=0,"",IF(H21=0,"n.a.",J21/H21)) | AE21: =IF(OR(COUNT(J21)=0,COUNT(AB21:AD21)<3),"",ROUND(J21-SUM(AB21:AD21),2)) | AF21: =IF(COUNT(AE21)=0,"",IF(Z21=0,"n.a.",AE21/Z21)) | AH21: =IF(OR(A21="",COUNT(Z21)=0,COUNT(AG21)=0),"",ROUND(Z21-AG21,2)) | AJ21: =IF(A21="","",IF(COUNT(I21)=0,"Enter approved NTE",IF(COUNT(Z21)>0,IF(Z21>I21,"Invoice exceeds NTE","Invoice within NTE"),IF(COUNT(L21)=0,"Enter quote inputs",IF(L21>I21,"Quote exceeds NTE","Quote within NTE"))))) | AK21: =IF(A21="","",IF(COUNT(H21)=0,"Enter direct cost",IF(COUNT(Z21)=0,"Enter invoice revenue",IF(COUNT(AB21:AD21)<3,"Enter expenses (0 if none)","Complete")))) | AL21: =IF(A21="","",IF(NOT(AND(COUNT(AH21)=1,N(AH21)>0.004,V21<>"Void",V21<>"Not invoiced",V21<>"Draft")),"",IF(COUNT(X21)=0,"No due date",IF(TODAY()-X21<=0,"Not yet due",IF(TODAY()-X21<=30,"1-30 days",IF(TODAY()-X21<=60,"31-60 days",IF(TODAY()-X21<=90,"61-90 days","Over 90 days"))))))) | AM21: =IF(OR(AL21="",AL21="No due date"),"",MAX(TODAY()-X21,0)) | AN21: =IF(AL21="","",IF(COUNT(X21)=0,-100000,TODAY()-X21)) | AO21: =IF(AN21="","",COUNTIF(AN$11:AN$1010,">"&AN21)+COUNTIF(AN$11:AN21,AN21)) | AP21: =IF(OR(A21="",B21=""),"",IF(COUNTIF(B$11:B21,B21)=1,MAX(AP$10:AP20)+1,""))
J22: =IF(OR(A22="",COUNT(H22)=0,COUNT(Z22)=0),"",ROUND(Z22-H22,2)) | K22: =IF(COUNT(J22)=0,"",IF(Z22=0,"n.a.",J22/Z22)) | L22: =IF(OR(A22="",COUNT(H22)=0,COUNT(Y22)=0),"",ROUND(H22*(1+Y22),2)) | X22: =IF(OR(A22="",COUNT(U22)=0,COUNT(AI22)=0),"",U22+AI22) | AA22: =IF(COUNT(J22)=0,"",IF(H22=0,"n.a.",J22/H22)) | AE22: =IF(OR(COUNT(J22)=0,COUNT(AB22:AD22)<3),"",ROUND(J22-SUM(AB22:AD22),2)) | AF22: =IF(COUNT(AE22)=0,"",IF(Z22=0,"n.a.",AE22/Z22)) | AH22: =IF(OR(A22="",COUNT(Z22)=0,COUNT(AG22)=0),"",ROUND(Z22-AG22,2)) | AJ22: =IF(A22="","",IF(COUNT(I22)=0,"Enter approved NTE",IF(COUNT(Z22)>0,IF(Z22>I22,"Invoice exceeds NTE","Invoice within NTE"),IF(COUNT(L22)=0,"Enter quote inputs",IF(L22>I22,"Quote exceeds NTE","Quote within NTE"))))) | AK22: =IF(A22="","",IF(COUNT(H22)=0,"Enter direct cost",IF(COUNT(Z22)=0,"Enter invoice revenue",IF(COUNT(AB22:AD22)<3,"Enter expenses (0 if none)","Complete")))) | AL22: =IF(A22="","",IF(NOT(AND(COUNT(AH22)=1,N(AH22)>0.004,V22<>"Void",V22<>"Not invoiced",V22<>"Draft")),"",IF(COUNT(X22)=0,"No due date",IF(TODAY()-X22<=0,"Not yet due",IF(TODAY()-X22<=30,"1-30 days",IF(TODAY()-X22<=60,"31-60 days",IF(TODAY()-X22<=90,"61-90 days","Over 90 days"))))))) | AM22: =IF(OR(AL22="",AL22="No due date"),"",MAX(TODAY()-X22,0)) | AN22: =IF(AL22="","",IF(COUNT(X22)=0,-100000,TODAY()-X22)) | AO22: =IF(AN22="","",COUNTIF(AN$11:AN$1010,">"&AN22)+COUNTIF(AN$11:AN22,AN22)) | AP22: =IF(OR(A22="",B22=""),"",IF(COUNTIF(B$11:B22,B22)=1,MAX(AP$10:AP21)+1,""))
... J1010: =IF(OR(A1010="",COUNT(H1010)=0,COUNT(Z1010)=0),"",ROUND(Z1010-H1010,2)) | K1010: =IF(COUNT(J1010)=0,"",IF(Z1010=0,"n.a.",J1010/Z1010)) | L1010: =IF(OR(A1010="",COUNT(H1010)=0,COUNT(Y1010)=0),"",ROUND(H1010*(1+Y1010),2)) | X1010: =IF(OR(A1010="",COUNT(U1010)=0,COUNT(AI1010)=0),"",U1010+AI1010) | AA1010: =IF(COUNT(J1010)=0,"",IF(H1010=0,"n.a.",J1010/H1010)) | AE1010: =IF(OR(COUNT(J1010)=0,COUNT(AB1010:AD1010)<3),"",ROUND(J1010-SUM(AB1010:AD1010),2)) | AF1010: =IF(COUNT(AE1010)=0,"",IF(Z1010=0,"n.a.",AE1010/Z1010)) | AH1010: =IF(OR(A1010="",COUNT(Z1010)=0,COUNT(AG1010)=0),"",ROUND(Z1010-AG1010,2)) | AJ1010: =IF(A1010="","",IF(COUNT(I1010)=0,"Enter approved NTE",IF(COUNT(Z1010)>0,IF(Z1010>I1010,"Invoice exceeds NTE","Invoice within NTE"),IF(COUNT(L1010)=0,"Enter quote inputs",IF(L1010>I1010,"Quote exceeds NTE","Quote within NTE"))))) | AK1010: =IF(A1010="","",IF(COUNT(H1010)=0,"Enter direct cost",IF(COUNT(Z1010)=0,"Enter invoice revenue",IF(COUNT(AB1010:AD1010)<3,"Enter expenses (0 if none)","Complete")))) | AL1010: =IF(A1010="","",IF(NOT(AND(COUNT(AH1010)=1,N(AH1010)>0.004,V1010<>"Void",V1010<>"Not invoiced",V1010<>"Draft")),"",IF(COUNT(X1010)=0,"No due date",IF(TODAY()-X1010<=0,"Not yet due",IF(TODAY()-X1010<=30,"1-30 days",IF(TODAY()-X1010<=60,"31-60 days",IF(TODAY()-X1010<=90,"61-90 days","Over 90 days"))))))) | AM1010: =IF(OR(AL1010="",AL1010="No due date"),"",MAX(TODAY()-X1010,0)) | AN1010: =IF(AL1010="","",IF(COUNT(X1010)=0,-100000,TODAY()-X1010)) | AO1010: =IF(AN1010="","",COUNTIF(AN$11:AN$1010,">"&AN1010)+COUNTIF(AN$11:AN1010,AN1010)) | AP1010: =IF(OR(A1010="",B1010=""),"",IF(COUNTIF(B$11:B1010,B1010)=1,MAX(AP$10:AP1009)+1,""))

Sheet Work Order Card
B2: Work Order Card
B3: Choose a WO # in the yellow box to see the whole job. Print with Ctrl+P.
B5: WO # | E5: =IF(C5="","◄ Choose or type a WO #",IF(H5="","WO # not found","")) | H5: =IF(C5="","",IFERROR(MATCH(C5,'Work Orders'!$A$11:$A$1010,0),""))
B7: Work order | E7: Cost & quote
B8: WO # | C8: =IF($H$5="","",IF(INDEX('Work Orders'!$A$11:$A$1010,$H$5)="","",INDEX('Work Orders'!$A$11:$A$1010,$H$5))) | E8: Direct cost | F8: =IF($H$5="","",IF(INDEX('Work Orders'!$H$11:$H$1010,$H$5)="","",INDEX('Work Orders'!$H$11:$H$1010,$H$5)))
B9: WO status | C9: =IF($H$5="","",IF(INDEX('Work Orders'!$R$11:$R$1010,$H$5)="","",INDEX('Work Orders'!$R$11:$R$1010,$H$5))) | E9: Target markup % | F9: =IF($H$5="","",IF(INDEX('Work Orders'!$Y$11:$Y$1010,$H$5)="","",INDEX('Work Orders'!$Y$11:$Y$1010,$H$5)))
B10: Client | C10: =IF($H$5="","",IF(INDEX('Work Orders'!$B$11:$B$1010,$H$5)="","",INDEX('Work Orders'!$B$11:$B$1010,$H$5))) | E10: Expected NTE / quote | F10: =IF($H$5="","",IF(INDEX('Work Orders'!$L$11:$L$1010,$H$5)="","",INDEX('Work Orders'!$L$11:$L$1010,$H$5)))
B11: Store name | C11: =IF($H$5="","",IF(INDEX('Work Orders'!$D$11:$D$1010,$H$5)="","",INDEX('Work Orders'!$D$11:$D$1010,$H$5))) | E11: Approved NTE | F11: =IF($H$5="","",IF(INDEX('Work Orders'!$I$11:$I$1010,$H$5)="","",INDEX('Work Orders'!$I$11:$I$1010,$H$5)))
B12: Location | C12: =IF($H$5="","",IF(INDEX('Work Orders'!$E$11:$E$1010,$H$5)="","",INDEX('Work Orders'!$E$11:$E$1010,$H$5))) | E12: NTE check | F12: =IF($H$5="","",IF(INDEX('Work Orders'!$AJ$11:$AJ$1010,$H$5)="","",INDEX('Work Orders'!$AJ$11:$AJ$1010,$H$5)))
B13: Date in | C13: =IF($H$5="","",IF(INDEX('Work Orders'!$T$11:$T$1010,$H$5)="","",INDEX('Work Orders'!$T$11:$T$1010,$H$5)))
B14: ETA | C14: =IF($H$5="","",IF(INDEX('Work Orders'!$F$11:$F$1010,$H$5)="","",INDEX('Work Orders'!$F$11:$F$1010,$H$5))) | E14: Invoice
B15: Job type / scope | C15: =IF($H$5="","",IF(INDEX('Work Orders'!$M$11:$M$1010,$H$5)="","",INDEX('Work Orders'!$M$11:$M$1010,$H$5))) | E15: Invoice # | F15: =IF($H$5="","",IF(INDEX('Work Orders'!$Q$11:$Q$1010,$H$5)="","",INDEX('Work Orders'!$Q$11:$Q$1010,$H$5)))
B16: Address | C16: =IF($H$5="","",IF(INDEX('Work Orders'!$S$11:$S$1010,$H$5)="","",INDEX('Work Orders'!$S$11:$S$1010,$H$5))) | E16: Invoice status | F16: =IF($H$5="","",IF(INDEX('Work Orders'!$V$11:$V$1010,$H$5)="","",INDEX('Work Orders'!$V$11:$V$1010,$H$5)))
E17: Invoice sent date | F17: =IF($H$5="","",IF(INDEX('Work Orders'!$U$11:$U$1010,$H$5)="","",INDEX('Work Orders'!$U$11:$U$1010,$H$5)))
B18: Team | E18: Payment terms (days) | F18: =IF($H$5="","",IF(INDEX('Work Orders'!$AI$11:$AI$1010,$H$5)="","",INDEX('Work Orders'!$AI$11:$AI$1010,$H$5)))
B19: Assignees | C19: =IF($H$5="","",IF(INDEX('Work Orders'!$C$11:$C$1010,$H$5)="","",INDEX('Work Orders'!$C$11:$C$1010,$H$5))) | E19: Payment due | F19: =IF($H$5="","",IF(INDEX('Work Orders'!$X$11:$X$1010,$H$5)="","",INDEX('Work Orders'!$X$11:$X$1010,$H$5)))
B20: Handler | C20: =IF($H$5="","",IF(INDEX('Work Orders'!$N$11:$N$1010,$H$5)="","",INDEX('Work Orders'!$N$11:$N$1010,$H$5))) | E20: Invoice revenue | F20: =IF($H$5="","",IF(INDEX('Work Orders'!$Z$11:$Z$1010,$H$5)="","",INDEX('Work Orders'!$Z$11:$Z$1010,$H$5)))
B21: Tech | C21: =IF($H$5="","",IF(INDEX('Work Orders'!$O$11:$O$1010,$H$5)="","",INDEX('Work Orders'!$O$11:$O$1010,$H$5))) | E21: Gross profit | F21: =IF($H$5="","",IF(INDEX('Work Orders'!$J$11:$J$1010,$H$5)="","",INDEX('Work Orders'!$J$11:$J$1010,$H$5)))
E22: Gross margin % | F22: =IF($H$5="","",IF(INDEX('Work Orders'!$K$11:$K$1010,$H$5)="","",INDEX('Work Orders'!$K$11:$K$1010,$H$5)))
B23: Parts & notes | E23: Actual markup % | F23: =IF($H$5="","",IF(INDEX('Work Orders'!$AA$11:$AA$1010,$H$5)="","",INDEX('Work Orders'!$AA$11:$AA$1010,$H$5)))
B24: Parts ordered / status | C24: =IF($H$5="","",IF(INDEX('Work Orders'!$G$11:$G$1010,$H$5)="","",INDEX('Work Orders'!$G$11:$G$1010,$H$5)))
B25: Notes | C25: =IF($H$5="","",IF(INDEX('Work Orders'!$P$11:$P$1010,$H$5)="","",INDEX('Work Orders'!$P$11:$P$1010,$H$5))) | E25: Expenses & net profit
E26: Allocated overhead | F26: =IF($H$5="","",IF(INDEX('Work Orders'!$AB$11:$AB$1010,$H$5)="","",INDEX('Work Orders'!$AB$11:$AB$1010,$H$5)))
B27: Receivables | E27: Payment / admin fees | F27: =IF($H$5="","",IF(INDEX('Work Orders'!$AC$11:$AC$1010,$H$5)="","",INDEX('Work Orders'!$AC$11:$AC$1010,$H$5)))
B28: Aging bucket | C28: =IF($H$5="","",IF(INDEX('Work Orders'!$AL$11:$AL$1010,$H$5)="","",INDEX('Work Orders'!$AL$11:$AL$1010,$H$5))) | E28: Other expenses / tax | F28: =IF($H$5="","",IF(INDEX('Work Orders'!$AD$11:$AD$1010,$H$5)="","",INDEX('Work Orders'!$AD$11:$AD$1010,$H$5)))
B29: Days overdue | C29: =IF($H$5="","",IF(INDEX('Work Orders'!$AM$11:$AM$1010,$H$5)="","",INDEX('Work Orders'!$AM$11:$AM$1010,$H$5))) | E29: Net profit | F29: =IF($H$5="","",IF(INDEX('Work Orders'!$AE$11:$AE$1010,$H$5)="","",INDEX('Work Orders'!$AE$11:$AE$1010,$H$5)))
E30: Net margin % | F30: =IF($H$5="","",IF(INDEX('Work Orders'!$AF$11:$AF$1010,$H$5)="","",INDEX('Work Orders'!$AF$11:$AF$1010,$H$5)))
E32: Payment
E33: Payment method | F33: =IF($H$5="","",IF(INDEX('Work Orders'!$W$11:$W$1010,$H$5)="","",INDEX('Work Orders'!$W$11:$W$1010,$H$5)))
E34: Amount received | F34: =IF($H$5="","",IF(INDEX('Work Orders'!$AG$11:$AG$1010,$H$5)="","",INDEX('Work Orders'!$AG$11:$AG$1010,$H$5)))
E35: Balance due | F35: =IF($H$5="","",IF(INDEX('Work Orders'!$AH$11:$AH$1010,$H$5)="","",INDEX('Work Orders'!$AH$11:$AH$1010,$H$5)))
E36: Financial input status | F36: =IF($H$5="","",IF(INDEX('Work Orders'!$AK$11:$AK$1010,$H$5)="","",INDEX('Work Orders'!$AK$11:$AK$1010,$H$5)))

Sheet Receivables
C2: Receivables
C3: Open balances on sent invoices, most overdue first. Updates automatically from the Work Orders sheet.
C4: Open balance | D4: =SUM(L7:L1006) | F4: Overdue | G4: =SUMIF(M7:M1006,">0",L7:L1006) | I4: Invoices open | J4: =COUNT(L7:L1006)
A6: # | B6: Row | C6: WO # | D6: Client | E6: Store name | F6: Invoice # | G6: Invoice status | H6: Invoice sent | I6: Payment due | J6: Invoice revenue | K6: Received | L6: Balance due | M6: Days overdue | N6: Aging | O6: Handler
A7: 1 | B7: =IFERROR(MATCH(A7,'Work Orders'!$AO$11:$AO$1010,0),"") | C7: =IF($B7="","",IF(INDEX('Work Orders'!$A$11:$A$1010,$B7)="","",INDEX('Work Orders'!$A$11:$A$1010,$B7))) | D7: =IF($B7="","",IF(INDEX('Work Orders'!$B$11:$B$1010,$B7)="","",INDEX('Work Orders'!$B$11:$B$1010,$B7))) | E7: =IF($B7="","",IF(INDEX('Work Orders'!$D$11:$D$1010,$B7)="","",INDEX('Work Orders'!$D$11:$D$1010,$B7))) | F7: =IF($B7="","",IF(INDEX('Work Orders'!$Q$11:$Q$1010,$B7)="","",INDEX('Work Orders'!$Q$11:$Q$1010,$B7))) | G7: =IF($B7="","",IF(INDEX('Work Orders'!$V$11:$V$1010,$B7)="","",INDEX('Work Orders'!$V$11:$V$1010,$B7))) | H7: =IF($B7="","",IF(INDEX('Work Orders'!$U$11:$U$1010,$B7)="","",INDEX('Work Orders'!$U$11:$U$1010,$B7))) | I7: =IF($B7="","",IF(INDEX('Work Orders'!$X$11:$X$1010,$B7)="","",INDEX('Work Orders'!$X$11:$X$1010,$B7))) | J7: =IF($B7="","",IF(INDEX('Work Orders'!$Z$11:$Z$1010,$B7)="","",INDEX('Work Orders'!$Z$11:$Z$1010,$B7))) | K7: =IF($B7="","",IF(INDEX('Work Orders'!$AG$11:$AG$1010,$B7)="","",INDEX('Work Orders'!$AG$11:$AG$1010,$B7))) | L7: =IF($B7="","",IF(INDEX('Work Orders'!$AH$11:$AH$1010,$B7)="","",INDEX('Work Orders'!$AH$11:$AH$1010,$B7))) | M7: =IF($B7="","",IF(INDEX('Work Orders'!$AM$11:$AM$1010,$B7)="","",INDEX('Work Orders'!$AM$11:$AM$1010,$B7))) | N7: =IF($B7="","",IF(INDEX('Work Orders'!$AL$11:$AL$1010,$B7)="","",INDEX('Work Orders'!$AL$11:$AL$1010,$B7))) | O7: =IF($B7="","",IF(INDEX('Work Orders'!$N$11:$N$1010,$B7)="","",INDEX('Work Orders'!$N$11:$N$1010,$B7)))
A8: 2 | B8: =IFERROR(MATCH(A8,'Work Orders'!$AO$11:$AO$1010,0),"") | C8: =IF($B8="","",IF(INDEX('Work Orders'!$A$11:$A$1010,$B8)="","",INDEX('Work Orders'!$A$11:$A$1010,$B8))) | D8: =IF($B8="","",IF(INDEX('Work Orders'!$B$11:$B$1010,$B8)="","",INDEX('Work Orders'!$B$11:$B$1010,$B8))) | E8: =IF($B8="","",IF(INDEX('Work Orders'!$D$11:$D$1010,$B8)="","",INDEX('Work Orders'!$D$11:$D$1010,$B8))) | F8: =IF($B8="","",IF(INDEX('Work Orders'!$Q$11:$Q$1010,$B8)="","",INDEX('Work Orders'!$Q$11:$Q$1010,$B8))) | G8: =IF($B8="","",IF(INDEX('Work Orders'!$V$11:$V$1010,$B8)="","",INDEX('Work Orders'!$V$11:$V$1010,$B8))) | H8: =IF($B8="","",IF(INDEX('Work Orders'!$U$11:$U$1010,$B8)="","",INDEX('Work Orders'!$U$11:$U$1010,$B8))) | I8: =IF($B8="","",IF(INDEX('Work Orders'!$X$11:$X$1010,$B8)="","",INDEX('Work Orders'!$X$11:$X$1010,$B8))) | J8: =IF($B8="","",IF(INDEX('Work Orders'!$Z$11:$Z$1010,$B8)="","",INDEX('Work Orders'!$Z$11:$Z$1010,$B8))) | K8: =IF($B8="","",IF(INDEX('Work Orders'!$AG$11:$AG$1010,$B8)="","",INDEX('Work Orders'!$AG$11:$AG$1010,$B8))) | L8: =IF($B8="","",IF(INDEX('Work Orders'!$AH$11:$AH$1010,$B8)="","",INDEX('Work Orders'!$AH$11:$AH$1010,$B8))) | M8: =IF($B8="","",IF(INDEX('Work Orders'!$AM$11:$AM$1010,$B8)="","",INDEX('Work Orders'!$AM$11:$AM$1010,$B8))) | N8: =IF($B8="","",IF(INDEX('Work Orders'!$AL$11:$AL$1010,$B8)="","",INDEX('Work Orders'!$AL$11:$AL$1010,$B8))) | O8: =IF($B8="","",IF(INDEX('Work Orders'!$N$11:$N$1010,$B8)="","",INDEX('Work Orders'!$N$11:$N$1010,$B8)))
A9: 3 | B9: =IFERROR(MATCH(A9,'Work Orders'!$AO$11:$AO$1010,0),"") | C9: =IF($B9="","",IF(INDEX('Work Orders'!$A$11:$A$1010,$B9)="","",INDEX('Work Orders'!$A$11:$A$1010,$B9))) | D9: =IF($B9="","",IF(INDEX('Work Orders'!$B$11:$B$1010,$B9)="","",INDEX('Work Orders'!$B$11:$B$1010,$B9))) | E9: =IF($B9="","",IF(INDEX('Work Orders'!$D$11:$D$1010,$B9)="","",INDEX('Work Orders'!$D$11:$D$1010,$B9))) | F9: =IF($B9="","",IF(INDEX('Work Orders'!$Q$11:$Q$1010,$B9)="","",INDEX('Work Orders'!$Q$11:$Q$1010,$B9))) | G9: =IF($B9="","",IF(INDEX('Work Orders'!$V$11:$V$1010,$B9)="","",INDEX('Work Orders'!$V$11:$V$1010,$B9))) | H9: =IF($B9="","",IF(INDEX('Work Orders'!$U$11:$U$1010,$B9)="","",INDEX('Work Orders'!$U$11:$U$1010,$B9))) | I9: =IF($B9="","",IF(INDEX('Work Orders'!$X$11:$X$1010,$B9)="","",INDEX('Work Orders'!$X$11:$X$1010,$B9))) | J9: =IF($B9="","",IF(INDEX('Work Orders'!$Z$11:$Z$1010,$B9)="","",INDEX('Work Orders'!$Z$11:$Z$1010,$B9))) | K9: =IF($B9="","",IF(INDEX('Work Orders'!$AG$11:$AG$1010,$B9)="","",INDEX('Work Orders'!$AG$11:$AG$1010,$B9))) | L9: =IF($B9="","",IF(INDEX('Work Orders'!$AH$11:$AH$1010,$B9)="","",INDEX('Work Orders'!$AH$11:$AH$1010,$B9))) | M9: =IF($B9="","",IF(INDEX('Work Orders'!$AM$11:$AM$1010,$B9)="","",INDEX('Work Orders'!$AM$11:$AM$1010,$B9))) | N9: =IF($B9="","",IF(INDEX('Work Orders'!$AL$11:$AL$1010,$B9)="","",INDEX('Work Orders'!$AL$11:$AL$1010,$B9))) | O9: =IF($B9="","",IF(INDEX('Work Orders'!$N$11:$N$1010,$B9)="","",INDEX('Work Orders'!$N$11:$N$1010,$B9)))
A10: 4 | B10: =IFERROR(MATCH(A10,'Work Orders'!$AO$11:$AO$1010,0),"") | C10: =IF($B10="","",IF(INDEX('Work Orders'!$A$11:$A$1010,$B10)="","",INDEX('Work Orders'!$A$11:$A$1010,$B10))) | D10: =IF($B10="","",IF(INDEX('Work Orders'!$B$11:$B$1010,$B10)="","",INDEX('Work Orders'!$B$11:$B$1010,$B10))) | E10: =IF($B10="","",IF(INDEX('Work Orders'!$D$11:$D$1010,$B10)="","",INDEX('Work Orders'!$D$11:$D$1010,$B10))) | F10: =IF($B10="","",IF(INDEX('Work Orders'!$Q$11:$Q$1010,$B10)="","",INDEX('Work Orders'!$Q$11:$Q$1010,$B10))) | G10: =IF($B10="","",IF(INDEX('Work Orders'!$V$11:$V$1010,$B10)="","",INDEX('Work Orders'!$V$11:$V$1010,$B10))) | H10: =IF($B10="","",IF(INDEX('Work Orders'!$U$11:$U$1010,$B10)="","",INDEX('Work Orders'!$U$11:$U$1010,$B10))) | I10: =IF($B10="","",IF(INDEX('Work Orders'!$X$11:$X$1010,$B10)="","",INDEX('Work Orders'!$X$11:$X$1010,$B10))) | J10: =IF($B10="","",IF(INDEX('Work Orders'!$Z$11:$Z$1010,$B10)="","",INDEX('Work Orders'!$Z$11:$Z$1010,$B10))) | K10: =IF($B10="","",IF(INDEX('Work Orders'!$AG$11:$AG$1010,$B10)="","",INDEX('Work Orders'!$AG$11:$AG$1010,$B10))) | L10: =IF($B10="","",IF(INDEX('Work Orders'!$AH$11:$AH$1010,$B10)="","",INDEX('Work Orders'!$AH$11:$AH$1010,$B10))) | M10: =IF($B10="","",IF(INDEX('Work Orders'!$AM$11:$AM$1010,$B10)="","",INDEX('Work Orders'!$AM$11:$AM$1010,$B10))) | N10: =IF($B10="","",IF(INDEX('Work Orders'!$AL$11:$AL$1010,$B10)="","",INDEX('Work Orders'!$AL$11:$AL$1010,$B10))) | O10: =IF($B10="","",IF(INDEX('Work Orders'!$N$11:$N$1010,$B10)="","",INDEX('Work Orders'!$N$11:$N$1010,$B10)))
A11: 5 | B11: =IFERROR(MATCH(A11,'Work Orders'!$AO$11:$AO$1010,0),"") | C11: =IF($B11="","",IF(INDEX('Work Orders'!$A$11:$A$1010,$B11)="","",INDEX('Work Orders'!$A$11:$A$1010,$B11))) | D11: =IF($B11="","",IF(INDEX('Work Orders'!$B$11:$B$1010,$B11)="","",INDEX('Work Orders'!$B$11:$B$1010,$B11))) | E11: =IF($B11="","",IF(INDEX('Work Orders'!$D$11:$D$1010,$B11)="","",INDEX('Work Orders'!$D$11:$D$1010,$B11))) | F11: =IF($B11="","",IF(INDEX('Work Orders'!$Q$11:$Q$1010,$B11)="","",INDEX('Work Orders'!$Q$11:$Q$1010,$B11))) | G11: =IF($B11="","",IF(INDEX('Work Orders'!$V$11:$V$1010,$B11)="","",INDEX('Work Orders'!$V$11:$V$1010,$B11))) | H11: =IF($B11="","",IF(INDEX('Work Orders'!$U$11:$U$1010,$B11)="","",INDEX('Work Orders'!$U$11:$U$1010,$B11))) | I11: =IF($B11="","",IF(INDEX('Work Orders'!$X$11:$X$1010,$B11)="","",INDEX('Work Orders'!$X$11:$X$1010,$B11))) | J11: =IF($B11="","",IF(INDEX('Work Orders'!$Z$11:$Z$1010,$B11)="","",INDEX('Work Orders'!$Z$11:$Z$1010,$B11))) | K11: =IF($B11="","",IF(INDEX('Work Orders'!$AG$11:$AG$1010,$B11)="","",INDEX('Work Orders'!$AG$11:$AG$1010,$B11))) | L11: =IF($B11="","",IF(INDEX('Work Orders'!$AH$11:$AH$1010,$B11)="","",INDEX('Work Orders'!$AH$11:$AH$1010,$B11))) | M11: =IF($B11="","",IF(INDEX('Work Orders'!$AM$11:$AM$1010,$B11)="","",INDEX('Work Orders'!$AM$11:$AM$1010,$B11))) | N11: =IF($B11="","",IF(INDEX('Work Orders'!$AL$11:$AL$1010,$B11)="","",INDEX('Work Orders'!$AL$11:$AL$1010,$B11))) | O11: =IF($B11="","",IF(INDEX('Work Orders'!$N$11:$N$1010,$B11)="","",INDEX('Work Orders'!$N$11:$N$1010,$B11)))
A12: 6 | B12: =IFERROR(MATCH(A12,'Work Orders'!$AO$11:$AO$1010,0),"") | C12: =IF($B12="","",IF(INDEX('Work Orders'!$A$11:$A$1010,$B12)="","",INDEX('Work Orders'!$A$11:$A$1010,$B12))) | D12: =IF($B12="","",IF(INDEX('Work Orders'!$B$11:$B$1010,$B12)="","",INDEX('Work Orders'!$B$11:$B$1010,$B12))) | E12: =IF($B12="","",IF(INDEX('Work Orders'!$D$11:$D$1010,$B12)="","",INDEX('Work Orders'!$D$11:$D$1010,$B12))) | F12: =IF($B12="","",IF(INDEX('Work Orders'!$Q$11:$Q$1010,$B12)="","",INDEX('Work Orders'!$Q$11:$Q$1010,$B12))) | G12: =IF($B12="","",IF(INDEX('Work Orders'!$V$11:$V$1010,$B12)="","",INDEX('Work Orders'!$V$11:$V$1010,$B12))) | H12: =IF($B12="","",IF(INDEX('Work Orders'!$U$11:$U$1010,$B12)="","",INDEX('Work Orders'!$U$11:$U$1010,$B12))) | I12: =IF($B12="","",IF(INDEX('Work Orders'!$X$11:$X$1010,$B12)="","",INDEX('Work Orders'!$X$11:$X$1010,$B12))) | J12: =IF($B12="","",IF(INDEX('Work Orders'!$Z$11:$Z$1010,$B12)="","",INDEX('Work Orders'!$Z$11:$Z$1010,$B12))) | K12: =IF($B12="","",IF(INDEX('Work Orders'!$AG$11:$AG$1010,$B12)="","",INDEX('Work Orders'!$AG$11:$AG$1010,$B12))) | L12: =IF($B12="","",IF(INDEX('Work Orders'!$AH$11:$AH$1010,$B12)="","",INDEX('Work Orders'!$AH$11:$AH$1010,$B12))) | M12: =IF($B12="","",IF(INDEX('Work Orders'!$AM$11:$AM$1010,$B12)="","",INDEX('Work Orders'!$AM$11:$AM$1010,$B12))) | N12: =IF($B12="","",IF(INDEX('Work Orders'!$AL$11:$AL$1010,$B12)="","",INDEX('Work Orders'!$AL$11:$AL$1010,$B12))) | O12: =IF($B12="","",IF(INDEX('Work Orders'!$N$11:$N$1010,$B12)="","",INDEX('Work Orders'!$N$11:$N$1010,$B12)))
A13: 7 | B13: =IFERROR(MATCH(A13,'Work Orders'!$AO$11:$AO$1010,0),"") | C13: =IF($B13="","",IF(INDEX('Work Orders'!$A$11:$A$1010,$B13)="","",INDEX('Work Orders'!$A$11:$A$1010,$B13))) | D13: =IF($B13="","",IF(INDEX('Work Orders'!$B$11:$B$1010,$B13)="","",INDEX('Work Orders'!$B$11:$B$1010,$B13))) | E13: =IF($B13="","",IF(INDEX('Work Orders'!$D$11:$D$1010,$B13)="","",INDEX('Work Orders'!$D$11:$D$1010,$B13))) | F13: =IF($B13="","",IF(INDEX('Work Orders'!$Q$11:$Q$1010,$B13)="","",INDEX('Work Orders'!$Q$11:$Q$1010,$B13))) | G13: =IF($B13="","",IF(INDEX('Work Orders'!$V$11:$V$1010,$B13)="","",INDEX('Work Orders'!$V$11:$V$1010,$B13))) | H13: =IF($B13="","",IF(INDEX('Work Orders'!$U$11:$U$1010,$B13)="","",INDEX('Work Orders'!$U$11:$U$1010,$B13))) | I13: =IF($B13="","",IF(INDEX('Work Orders'!$X$11:$X$1010,$B13)="","",INDEX('Work Orders'!$X$11:$X$1010,$B13))) | J13: =IF($B13="","",IF(INDEX('Work Orders'!$Z$11:$Z$1010,$B13)="","",INDEX('Work Orders'!$Z$11:$Z$1010,$B13))) | K13: =IF($B13="","",IF(INDEX('Work Orders'!$AG$11:$AG$1010,$B13)="","",INDEX('Work Orders'!$AG$11:$AG$1010,$B13))) | L13: =IF($B13="","",IF(INDEX('Work Orders'!$AH$11:$AH$1010,$B13)="","",INDEX('Work Orders'!$AH$11:$AH$1010,$B13))) | M13: =IF($B13="","",IF(INDEX('Work Orders'!$AM$11:$AM$1010,$B13)="","",INDEX('Work Orders'!$AM$11:$AM$1010,$B13))) | N13: =IF($B13="","",IF(INDEX('Work Orders'!$AL$11:$AL$1010,$B13)="","",INDEX('Work Orders'!$AL$11:$AL$1010,$B13))) | O13: =IF($B13="","",IF(INDEX('Work Orders'!$N$11:$N$1010,$B13)="","",INDEX('Work Orders'!$N$11:$N$1010,$B13)))
A14: 8 | B14: =IFERROR(MATCH(A14,'Work Orders'!$AO$11:$AO$1010,0),"") | C14: =IF($B14="","",IF(INDEX('Work Orders'!$A$11:$A$1010,$B14)="","",INDEX('Work Orders'!$A$11:$A$1010,$B14))) | D14: =IF($B14="","",IF(INDEX('Work Orders'!$B$11:$B$1010,$B14)="","",INDEX('Work Orders'!$B$11:$B$1010,$B14))) | E14: =IF($B14="","",IF(INDEX('Work Orders'!$D$11:$D$1010,$B14)="","",INDEX('Work Orders'!$D$11:$D$1010,$B14))) | F14: =IF($B14="","",IF(INDEX('Work Orders'!$Q$11:$Q$1010,$B14)="","",INDEX('Work Orders'!$Q$11:$Q$1010,$B14))) | G14: =IF($B14="","",IF(INDEX('Work Orders'!$V$11:$V$1010,$B14)="","",INDEX('Work Orders'!$V$11:$V$1010,$B14))) | H14: =IF($B14="","",IF(INDEX('Work Orders'!$U$11:$U$1010,$B14)="","",INDEX('Work Orders'!$U$11:$U$1010,$B14))) | I14: =IF($B14="","",IF(INDEX('Work Orders'!$X$11:$X$1010,$B14)="","",INDEX('Work Orders'!$X$11:$X$1010,$B14))) | J14: =IF($B14="","",IF(INDEX('Work Orders'!$Z$11:$Z$1010,$B14)="","",INDEX('Work Orders'!$Z$11:$Z$1010,$B14))) | K14: =IF($B14="","",IF(INDEX('Work Orders'!$AG$11:$AG$1010,$B14)="","",INDEX('Work Orders'!$AG$11:$AG$1010,$B14))) | L14: =IF($B14="","",IF(INDEX('Work Orders'!$AH$11:$AH$1010,$B14)="","",INDEX('Work Orders'!$AH$11:$AH$1010,$B14))) | M14: =IF($B14="","",IF(INDEX('Work Orders'!$AM$11:$AM$1010,$B14)="","",INDEX('Work Orders'!$AM$11:$AM$1010,$B14))) | N14: =IF($B14="","",IF(INDEX('Work Orders'!$AL$11:$AL$1010,$B14)="","",INDEX('Work Orders'!$AL$11:$AL$1010,$B14))) | O14: =IF($B14="","",IF(INDEX('Work Orders'!$N$11:$N$1010,$B14)="","",INDEX('Work Orders'!$N$11:$N$1010,$B14)))
A15: 9 | B15: =IFERROR(MATCH(A15,'Work Orders'!$AO$11:$AO$1010,0),"") | C15: =IF($B15="","",IF(INDEX('Work Orders'!$A$11:$A$1010,$B15)="","",INDEX('Work Orders'!$A$11:$A$1010,$B15))) | D15: =IF($B15="","",IF(INDEX('Work Orders'!$B$11:$B$1010,$B15)="","",INDEX('Work Orders'!$B$11:$B$1010,$B15))) | E15: =IF($B15="","",IF(INDEX('Work Orders'!$D$11:$D$1010,$B15)="","",INDEX('Work Orders'!$D$11:$D$1010,$B15))) | F15: =IF($B15="","",IF(INDEX('Work Orders'!$Q$11:$Q$1010,$B15)="","",INDEX('Work Orders'!$Q$11:$Q$1010,$B15))) | G15: =IF($B15="","",IF(INDEX('Work Orders'!$V$11:$V$1010,$B15)="","",INDEX('Work Orders'!$V$11:$V$1010,$B15))) | H15: =IF($B15="","",IF(INDEX('Work Orders'!$U$11:$U$1010,$B15)="","",INDEX('Work Orders'!$U$11:$U$1010,$B15))) | I15: =IF($B15="","",IF(INDEX('Work Orders'!$X$11:$X$1010,$B15)="","",INDEX('Work Orders'!$X$11:$X$1010,$B15))) | J15: =IF($B15="","",IF(INDEX('Work Orders'!$Z$11:$Z$1010,$B15)="","",INDEX('Work Orders'!$Z$11:$Z$1010,$B15))) | K15: =IF($B15="","",IF(INDEX('Work Orders'!$AG$11:$AG$1010,$B15)="","",INDEX('Work Orders'!$AG$11:$AG$1010,$B15))) | L15: =IF($B15="","",IF(INDEX('Work Orders'!$AH$11:$AH$1010,$B15)="","",INDEX('Work Orders'!$AH$11:$AH$1010,$B15))) | M15: =IF($B15="","",IF(INDEX('Work Orders'!$AM$11:$AM$1010,$B15)="","",INDEX('Work Orders'!$AM$11:$AM$1010,$B15))) | N15: =IF($B15="","",IF(INDEX('Work Orders'!$AL$11:$AL$1010,$B15)="","",INDEX('Work Orders'!$AL$11:$AL$1010,$B15))) | O15: =IF($B15="","",IF(INDEX('Work Orders'!$N$11:$N$1010,$B15)="","",INDEX('Work Orders'!$N$11:$N$1010,$B15)))
A16: 10 | B16: =IFERROR(MATCH(A16,'Work Orders'!$AO$11:$AO$1010,0),"") | C16: =IF($B16="","",IF(INDEX('Work Orders'!$A$11:$A$1010,$B16)="","",INDEX('Work Orders'!$A$11:$A$1010,$B16))) | D16: =IF($B16="","",IF(INDEX('Work Orders'!$B$11:$B$1010,$B16)="","",INDEX('Work Orders'!$B$11:$B$1010,$B16))) | E16: =IF($B16="","",IF(INDEX('Work Orders'!$D$11:$D$1010,$B16)="","",INDEX('Work Orders'!$D$11:$D$1010,$B16))) | F16: =IF($B16="","",IF(INDEX('Work Orders'!$Q$11:$Q$1010,$B16)="","",INDEX('Work Orders'!$Q$11:$Q$1010,$B16))) | G16: =IF($B16="","",IF(INDEX('Work Orders'!$V$11:$V$1010,$B16)="","",INDEX('Work Orders'!$V$11:$V$1010,$B16))) | H16: =IF($B16="","",IF(INDEX('Work Orders'!$U$11:$U$1010,$B16)="","",INDEX('Work Orders'!$U$11:$U$1010,$B16))) | I16: =IF($B16="","",IF(INDEX('Work Orders'!$X$11:$X$1010,$B16)="","",INDEX('Work Orders'!$X$11:$X$1010,$B16))) | J16: =IF($B16="","",IF(INDEX('Work Orders'!$Z$11:$Z$1010,$B16)="","",INDEX('Work Orders'!$Z$11:$Z$1010,$B16))) | K16: =IF($B16="","",IF(INDEX('Work Orders'!$AG$11:$AG$1010,$B16)="","",INDEX('Work Orders'!$AG$11:$AG$1010,$B16))) | L16: =IF($B16="","",IF(INDEX('Work Orders'!$AH$11:$AH$1010,$B16)="","",INDEX('Work Orders'!$AH$11:$AH$1010,$B16))) | M16: =IF($B16="","",IF(INDEX('Work Orders'!$AM$11:$AM$1010,$B16)="","",INDEX('Work Orders'!$AM$11:$AM$1010,$B16))) | N16: =IF($B16="","",IF(INDEX('Work Orders'!$AL$11:$AL$1010,$B16)="","",INDEX('Work Orders'!$AL$11:$AL$1010,$B16))) | O16: =IF($B16="","",IF(INDEX('Work Orders'!$N$11:$N$1010,$B16)="","",INDEX('Work Orders'!$N$11:$N$1010,$B16)))
A17: 11 | B17: =IFERROR(MATCH(A17,'Work Orders'!$AO$11:$AO$1010,0),"") | C17: =IF($B17="","",IF(INDEX('Work Orders'!$A$11:$A$1010,$B17)="","",INDEX('Work Orders'!$A$11:$A$1010,$B17))) | D17: =IF($B17="","",IF(INDEX('Work Orders'!$B$11:$B$1010,$B17)="","",INDEX('Work Orders'!$B$11:$B$1010,$B17))) | E17: =IF($B17="","",IF(INDEX('Work Orders'!$D$11:$D$1010,$B17)="","",INDEX('Work Orders'!$D$11:$D$1010,$B17))) | F17: =IF($B17="","",IF(INDEX('Work Orders'!$Q$11:$Q$1010,$B17)="","",INDEX('Work Orders'!$Q$11:$Q$1010,$B17))) | G17: =IF($B17="","",IF(INDEX('Work Orders'!$V$11:$V$1010,$B17)="","",INDEX('Work Orders'!$V$11:$V$1010,$B17))) | H17: =IF($B17="","",IF(INDEX('Work Orders'!$U$11:$U$1010,$B17)="","",INDEX('Work Orders'!$U$11:$U$1010,$B17))) | I17: =IF($B17="","",IF(INDEX('Work Orders'!$X$11:$X$1010,$B17)="","",INDEX('Work Orders'!$X$11:$X$1010,$B17))) | J17: =IF($B17="","",IF(INDEX('Work Orders'!$Z$11:$Z$1010,$B17)="","",INDEX('Work Orders'!$Z$11:$Z$1010,$B17))) | K17: =IF($B17="","",IF(INDEX('Work Orders'!$AG$11:$AG$1010,$B17)="","",INDEX('Work Orders'!$AG$11:$AG$1010,$B17))) | L17: =IF($B17="","",IF(INDEX('Work Orders'!$AH$11:$AH$1010,$B17)="","",INDEX('Work Orders'!$AH$11:$AH$1010,$B17))) | M17: =IF($B17="","",IF(INDEX('Work Orders'!$AM$11:$AM$1010,$B17)="","",INDEX('Work Orders'!$AM$11:$AM$1010,$B17))) | N17: =IF($B17="","",IF(INDEX('Work Orders'!$AL$11:$AL$1010,$B17)="","",INDEX('Work Orders'!$AL$11:$AL$1010,$B17))) | O17: =IF($B17="","",IF(INDEX('Work Orders'!$N$11:$N$1010,$B17)="","",INDEX('Work Orders'!$N$11:$N$1010,$B17)))
A18: 12 | B18: =IFERROR(MATCH(A18,'Work Orders'!$AO$11:$AO$1010,0),"") | C18: =IF($B18="","",IF(INDEX('Work Orders'!$A$11:$A$1010,$B18)="","",INDEX('Work Orders'!$A$11:$A$1010,$B18))) | D18: =IF($B18="","",IF(INDEX('Work Orders'!$B$11:$B$1010,$B18)="","",INDEX('Work Orders'!$B$11:$B$1010,$B18))) | E18: =IF($B18="","",IF(INDEX('Work Orders'!$D$11:$D$1010,$B18)="","",INDEX('Work Orders'!$D$11:$D$1010,$B18))) | F18: =IF($B18="","",IF(INDEX('Work Orders'!$Q$11:$Q$1010,$B18)="","",INDEX('Work Orders'!$Q$11:$Q$1010,$B18))) | G18: =IF($B18="","",IF(INDEX('Work Orders'!$V$11:$V$1010,$B18)="","",INDEX('Work Orders'!$V$11:$V$1010,$B18))) | H18: =IF($B18="","",IF(INDEX('Work Orders'!$U$11:$U$1010,$B18)="","",INDEX('Work Orders'!$U$11:$U$1010,$B18))) | I18: =IF($B18="","",IF(INDEX('Work Orders'!$X$11:$X$1010,$B18)="","",INDEX('Work Orders'!$X$11:$X$1010,$B18))) | J18: =IF($B18="","",IF(INDEX('Work Orders'!$Z$11:$Z$1010,$B18)="","",INDEX('Work Orders'!$Z$11:$Z$1010,$B18))) | K18: =IF($B18="","",IF(INDEX('Work Orders'!$AG$11:$AG$1010,$B18)="","",INDEX('Work Orders'!$AG$11:$AG$1010,$B18))) | L18: =IF($B18="","",IF(INDEX('Work Orders'!$AH$11:$AH$1010,$B18)="","",INDEX('Work Orders'!$AH$11:$AH$1010,$B18))) | M18: =IF($B18="","",IF(INDEX('Work Orders'!$AM$11:$AM$1010,$B18)="","",INDEX('Work Orders'!$AM$11:$AM$1010,$B18))) | N18: =IF($B18="","",IF(INDEX('Work Orders'!$AL$11:$AL$1010,$B18)="","",INDEX('Work Orders'!$AL$11:$AL$1010,$B18))) | O18: =IF($B18="","",IF(INDEX('Work Orders'!$N$11:$N$1010,$B18)="","",INDEX('Work Orders'!$N$11:$N$1010,$B18)))
... A1006: 1000 | B1006: =IFERROR(MATCH(A1006,'Work Orders'!$AO$11:$AO$1010,0),"") | C1006: =IF($B1006="","",IF(INDEX('Work Orders'!$A$11:$A$1010,$B1006)="","",INDEX('Work Orders'!$A$11:$A$1010,$B1006))) | D1006: =IF($B1006="","",IF(INDEX('Work Orders'!$B$11:$B$1010,$B1006)="","",INDEX('Work Orders'!$B$11:$B$1010,$B1006))) | E1006: =IF($B1006="","",IF(INDEX('Work Orders'!$D$11:$D$1010,$B1006)="","",INDEX('Work Orders'!$D$11:$D$1010,$B1006))) | F1006: =IF($B1006="","",IF(INDEX('Work Orders'!$Q$11:$Q$1010,$B1006)="","",INDEX('Work Orders'!$Q$11:$Q$1010,$B1006))) | G1006: =IF($B1006="","",IF(INDEX('Work Orders'!$V$11:$V$1010,$B1006)="","",INDEX('Work Orders'!$V$11:$V$1010,$B1006))) | H1006: =IF($B1006="","",IF(INDEX('Work Orders'!$U$11:$U$1010,$B1006)="","",INDEX('Work Orders'!$U$11:$U$1010,$B1006))) | I1006: =IF($B1006="","",IF(INDEX('Work Orders'!$X$11:$X$1010,$B1006)="","",INDEX('Work Orders'!$X$11:$X$1010,$B1006))) | J1006: =IF($B1006="","",IF(INDEX('Work Orders'!$Z$11:$Z$1010,$B1006)="","",INDEX('Work Orders'!$Z$11:$Z$1010,$B1006))) | K1006: =IF($B1006="","",IF(INDEX('Work Orders'!$AG$11:$AG$1010,$B1006)="","",INDEX('Work Orders'!$AG$11:$AG$1010,$B1006))) | L1006: =IF($B1006="","",IF(INDEX('Work Orders'!$AH$11:$AH$1010,$B1006)="","",INDEX('Work Orders'!$AH$11:$AH$1010,$B1006))) | M1006: =IF($B1006="","",IF(INDEX('Work Orders'!$AM$11:$AM$1010,$B1006)="","",INDEX('Work Orders'!$AM$11:$AM$1010,$B1006))) | N1006: =IF($B1006="","",IF(INDEX('Work Orders'!$AL$11:$AL$1010,$B1006)="","",INDEX('Work Orders'!$AL$11:$AL$1010,$B1006))) | O1006: =IF($B1006="","",IF(INDEX('Work Orders'!$N$11:$N$1010,$B1006)="","",INDEX('Work Orders'!$N$11:$N$1010,$B1006)))

Sheet Clients
B2: Clients
B3: Totals per client from the Work Orders sheet. Clients appear in the order they were first entered.
B4: Total | C4: =SUM(C6:C205) | D4: =SUM(D6:D205) | E4: =SUM(E6:E205) | F4: =SUM(F6:F205) | G4: =SUM(G6:G205) | H4: =SUM(H6:H205)
A5: # | B5: Client | C5: Work orders | D5: Invoice revenue | E5: Gross profit | F5: Net profit | G5: Balance due | H5: Overdue | I5: Revenue rank
A6: 1 | B6: =IFERROR(INDEX('Work Orders'!$B$11:$B$1010,MATCH(A6,'Work Orders'!$AP$11:$AP$1010,0)),"") | C6: =IF(B6="","",COUNTIFS('Work Orders'!$B$11:$B$1010,B6,'Work Orders'!$A$11:$A$1010,"<>")) | D6: =IF(B6="","",SUMIFS('Work Orders'!$Z$11:$Z$1010,'Work Orders'!$B$11:$B$1010,B6)) | E6: =IF(B6="","",SUMIFS('Work Orders'!$J$11:$J$1010,'Work Orders'!$B$11:$B$1010,B6)) | F6: =IF(B6="","",SUMIFS('Work Orders'!$AE$11:$AE$1010,'Work Orders'!$B$11:$B$1010,B6)) | G6: =IF(B6="","",SUMIFS('Work Orders'!$AH$11:$AH$1010,'Work Orders'!$B$11:$B$1010,B6)) | H6: =IF(B6="","",SUMIFS('Work Orders'!$AH$11:$AH$1010,'Work Orders'!$B$11:$B$1010,B6,'Work Orders'!$AM$11:$AM$1010,">0")) | I6: =IF(B6="","",COUNTIF(D$6:D$205,">"&D6)+COUNTIF(D$6:D6,D6))
A7: 2 | B7: =IFERROR(INDEX('Work Orders'!$B$11:$B$1010,MATCH(A7,'Work Orders'!$AP$11:$AP$1010,0)),"") | C7: =IF(B7="","",COUNTIFS('Work Orders'!$B$11:$B$1010,B7,'Work Orders'!$A$11:$A$1010,"<>")) | D7: =IF(B7="","",SUMIFS('Work Orders'!$Z$11:$Z$1010,'Work Orders'!$B$11:$B$1010,B7)) | E7: =IF(B7="","",SUMIFS('Work Orders'!$J$11:$J$1010,'Work Orders'!$B$11:$B$1010,B7)) | F7: =IF(B7="","",SUMIFS('Work Orders'!$AE$11:$AE$1010,'Work Orders'!$B$11:$B$1010,B7)) | G7: =IF(B7="","",SUMIFS('Work Orders'!$AH$11:$AH$1010,'Work Orders'!$B$11:$B$1010,B7)) | H7: =IF(B7="","",SUMIFS('Work Orders'!$AH$11:$AH$1010,'Work Orders'!$B$11:$B$1010,B7,'Work Orders'!$AM$11:$AM$1010,">0")) | I7: =IF(B7="","",COUNTIF(D$6:D$205,">"&D7)+COUNTIF(D$6:D7,D7))
A8: 3 | B8: =IFERROR(INDEX('Work Orders'!$B$11:$B$1010,MATCH(A8,'Work Orders'!$AP$11:$AP$1010,0)),"") | C8: =IF(B8="","",COUNTIFS('Work Orders'!$B$11:$B$1010,B8,'Work Orders'!$A$11:$A$1010,"<>")) | D8: =IF(B8="","",SUMIFS('Work Orders'!$Z$11:$Z$1010,'Work Orders'!$B$11:$B$1010,B8)) | E8: =IF(B8="","",SUMIFS('Work Orders'!$J$11:$J$1010,'Work Orders'!$B$11:$B$1010,B8)) | F8: =IF(B8="","",SUMIFS('Work Orders'!$AE$11:$AE$1010,'Work Orders'!$B$11:$B$1010,B8)) | G8: =IF(B8="","",SUMIFS('Work Orders'!$AH$11:$AH$1010,'Work Orders'!$B$11:$B$1010,B8)) | H8: =IF(B8="","",SUMIFS('Work Orders'!$AH$11:$AH$1010,'Work Orders'!$B$11:$B$1010,B8,'Work Orders'!$AM$11:$AM$1010,">0")) | I8: =IF(B8="","",COUNTIF(D$6:D$205,">"&D8)+COUNTIF(D$6:D8,D8))
A9: 4 | B9: =IFERROR(INDEX('Work Orders'!$B$11:$B$1010,MATCH(A9,'Work Orders'!$AP$11:$AP$1010,0)),"") | C9: =IF(B9="","",COUNTIFS('Work Orders'!$B$11:$B$1010,B9,'Work Orders'!$A$11:$A$1010,"<>")) | D9: =IF(B9="","",SUMIFS('Work Orders'!$Z$11:$Z$1010,'Work Orders'!$B$11:$B$1010,B9)) | E9: =IF(B9="","",SUMIFS('Work Orders'!$J$11:$J$1010,'Work Orders'!$B$11:$B$1010,B9)) | F9: =IF(B9="","",SUMIFS('Work Orders'!$AE$11:$AE$1010,'Work Orders'!$B$11:$B$1010,B9)) | G9: =IF(B9="","",SUMIFS('Work Orders'!$AH$11:$AH$1010,'Work Orders'!$B$11:$B$1010,B9)) | H9: =IF(B9="","",SUMIFS('Work Orders'!$AH$11:$AH$1010,'Work Orders'!$B$11:$B$1010,B9,'Work Orders'!$AM$11:$AM$1010,">0")) | I9: =IF(B9="","",COUNTIF(D$6:D$205,">"&D9)+COUNTIF(D$6:D9,D9))
A10: 5 | B10: =IFERROR(INDEX('Work Orders'!$B$11:$B$1010,MATCH(A10,'Work Orders'!$AP$11:$AP$1010,0)),"") | C10: =IF(B10="","",COUNTIFS('Work Orders'!$B$11:$B$1010,B10,'Work Orders'!$A$11:$A$1010,"<>")) | D10: =IF(B10="","",SUMIFS('Work Orders'!$Z$11:$Z$1010,'Work Orders'!$B$11:$B$1010,B10)) | E10: =IF(B10="","",SUMIFS('Work Orders'!$J$11:$J$1010,'Work Orders'!$B$11:$B$1010,B10)) | F10: =IF(B10="","",SUMIFS('Work Orders'!$AE$11:$AE$1010,'Work Orders'!$B$11:$B$1010,B10)) | G10: =IF(B10="","",SUMIFS('Work Orders'!$AH$11:$AH$1010,'Work Orders'!$B$11:$B$1010,B10)) | H10: =IF(B10="","",SUMIFS('Work Orders'!$AH$11:$AH$1010,'Work Orders'!$B$11:$B$1010,B10,'Work Orders'!$AM$11:$AM$1010,">0")) | I10: =IF(B10="","",COUNTIF(D$6:D$205,">"&D10)+COUNTIF(D$6:D10,D10))
A11: 6 | B11: =IFERROR(INDEX('Work Orders'!$B$11:$B$1010,MATCH(A11,'Work Orders'!$AP$11:$AP$1010,0)),"") | C11: =IF(B11="","",COUNTIFS('Work Orders'!$B$11:$B$1010,B11,'Work Orders'!$A$11:$A$1010,"<>")) | D11: =IF(B11="","",SUMIFS('Work Orders'!$Z$11:$Z$1010,'Work Orders'!$B$11:$B$1010,B11)) | E11: =IF(B11="","",SUMIFS('Work Orders'!$J$11:$J$1010,'Work Orders'!$B$11:$B$1010,B11)) | F11: =IF(B11="","",SUMIFS('Work Orders'!$AE$11:$AE$1010,'Work Orders'!$B$11:$B$1010,B11)) | G11: =IF(B11="","",SUMIFS('Work Orders'!$AH$11:$AH$1010,'Work Orders'!$B$11:$B$1010,B11)) | H11: =IF(B11="","",SUMIFS('Work Orders'!$AH$11:$AH$1010,'Work Orders'!$B$11:$B$1010,B11,'Work Orders'!$AM$11:$AM$1010,">0")) | I11: =IF(B11="","",COUNTIF(D$6:D$205,">"&D11)+COUNTIF(D$6:D11,D11))
A12: 7 | B12: =IFERROR(INDEX('Work Orders'!$B$11:$B$1010,MATCH(A12,'Work Orders'!$AP$11:$AP$1010,0)),"") | C12: =IF(B12="","",COUNTIFS('Work Orders'!$B$11:$B$1010,B12,'Work Orders'!$A$11:$A$1010,"<>")) | D12: =IF(B12="","",SUMIFS('Work Orders'!$Z$11:$Z$1010,'Work Orders'!$B$11:$B$1010,B12)) | E12: =IF(B12="","",SUMIFS('Work Orders'!$J$11:$J$1010,'Work Orders'!$B$11:$B$1010,B12)) | F12: =IF(B12="","",SUMIFS('Work Orders'!$AE$11:$AE$1010,'Work Orders'!$B$11:$B$1010,B12)) | G12: =IF(B12="","",SUMIFS('Work Orders'!$AH$11:$AH$1010,'Work Orders'!$B$11:$B$1010,B12)) | H12: =IF(B12="","",SUMIFS('Work Orders'!$AH$11:$AH$1010,'Work Orders'!$B$11:$B$1010,B12,'Work Orders'!$AM$11:$AM$1010,">0")) | I12: =IF(B12="","",COUNTIF(D$6:D$205,">"&D12)+COUNTIF(D$6:D12,D12))
A13: 8 | B13: =IFERROR(INDEX('Work Orders'!$B$11:$B$1010,MATCH(A13,'Work Orders'!$AP$11:$AP$1010,0)),"") | C13: =IF(B13="","",COUNTIFS('Work Orders'!$B$11:$B$1010,B13,'Work Orders'!$A$11:$A$1010,"<>")) | D13: =IF(B13="","",SUMIFS('Work Orders'!$Z$11:$Z$1010,'Work Orders'!$B$11:$B$1010,B13)) | E13: =IF(B13="","",SUMIFS('Work Orders'!$J$11:$J$1010,'Work Orders'!$B$11:$B$1010,B13)) | F13: =IF(B13="","",SUMIFS('Work Orders'!$AE$11:$AE$1010,'Work Orders'!$B$11:$B$1010,B13)) | G13: =IF(B13="","",SUMIFS('Work Orders'!$AH$11:$AH$1010,'Work Orders'!$B$11:$B$1010,B13)) | H13: =IF(B13="","",SUMIFS('Work Orders'!$AH$11:$AH$1010,'Work Orders'!$B$11:$B$1010,B13,'Work Orders'!$AM$11:$AM$1010,">0")) | I13: =IF(B13="","",COUNTIF(D$6:D$205,">"&D13)+COUNTIF(D$6:D13,D13))
A14: 9 | B14: =IFERROR(INDEX('Work Orders'!$B$11:$B$1010,MATCH(A14,'Work Orders'!$AP$11:$AP$1010,0)),"") | C14: =IF(B14="","",COUNTIFS('Work Orders'!$B$11:$B$1010,B14,'Work Orders'!$A$11:$A$1010,"<>")) | D14: =IF(B14="","",SUMIFS('Work Orders'!$Z$11:$Z$1010,'Work Orders'!$B$11:$B$1010,B14)) | E14: =IF(B14="","",SUMIFS('Work Orders'!$J$11:$J$1010,'Work Orders'!$B$11:$B$1010,B14)) | F14: =IF(B14="","",SUMIFS('Work Orders'!$AE$11:$AE$1010,'Work Orders'!$B$11:$B$1010,B14)) | G14: =IF(B14="","",SUMIFS('Work Orders'!$AH$11:$AH$1010,'Work Orders'!$B$11:$B$1010,B14)) | H14: =IF(B14="","",SUMIFS('Work Orders'!$AH$11:$AH$1010,'Work Orders'!$B$11:$B$1010,B14,'Work Orders'!$AM$11:$AM$1010,">0")) | I14: =IF(B14="","",COUNTIF(D$6:D$205,">"&D14)+COUNTIF(D$6:D14,D14))
